<?xml version="1.0" encoding="utf-8"?>
<!-- This URDF was automatically created by SolidWorks to URDF Exporter! Originally created by Stephen Brawner (brawner@gmail.com) 
     Commit Version: 1.6.0-1-g15f4949  Build Version: 1.6.7594.29634
     For more information, please see http://wiki.ros.org/sw_urdf_exporter -->
<robot
  name="quadf">
  <link
    name="base">
    <inertial>
      <origin
        xyz="-1.70385490158136E-14 -0.0138235985731072 -0.0264324777192774"
        rpy="0 0 0" />
      <mass
        value="2.37381544603402" />
      <inertia
        ixx="0.0209437152991633"
        ixy="0.000287352021558558"
        ixz="3.32615269885488E-16"
        iyy="0.0143486188433564"
        iyz="-9.24316639678872E-17"
        izz="0.03292339027832" />
    </inertial>
    <visual>
      <origin
        xyz="0 0 0"
        rpy="0 0 0" />
      <geometry>
        <mesh
          filename="package://quadf/meshes/base.stl" />
      </geometry>
      <material
        name="">
        <color
          rgba="0.792156862745098 0.819607843137255 0.933333333333333 1" />
      </material>
    </visual>
    <collision>
      <origin
        xyz="0 0 0"
        rpy="0 0 0" />
      <geometry>
        <mesh
          filename="package://quadf/meshes/base.stl" />
      </geometry>
    </collision>
  </link>
  <link
    name="front left hip">
    <inertial>
      <origin
        xyz="-0.000727243703443653 0.0921123421932154 -0.000198984132469628"
        rpy="0 0 0" />
      <mass
        value="0.601866556488004" />
      <inertia
        ixx="0.00596933210385933"
        ixy="0.000111385467813034"
        ixz="-2.6913154908652E-06"
        iyy="0.000696524079127736"
        iyz="1.55670120225854E-05"
        izz="0.00572460287072933" />
    </inertial>
    <visual>
      <origin
        xyz="0 0 0"
        rpy="0 0 0" />
      <geometry>
        <mesh
          filename="package://quadf/meshes/front left hip.stl" />
      </geometry>
      <material
        name="">
        <color
          rgba="0.792156862745098 0.819607843137255 0.933333333333333 1" />
      </material>
    </visual>
    <collision>
      <origin
        xyz="0 0 0"
        rpy="0 0 0" />
      <geometry>
        <mesh
          filename="package://quadf/meshes/front left hip.stl" />
      </geometry>
    </collision>
  </link>
  <joint
    name="front left hip joint"
    type="revolute">
    <origin
      xyz="-0.125000000000013 0.282500000000001 -0.0266306081677672"
      rpy="0 0 -3.14159265358979" />
    <parent
      link="base" />
    <child
      link="front left hip" />
    <axis
      xyz="0 1 0" />
    <limit
      lower="-3.14"
      upper="3.14"
      effort="9"
      velocity="5" />
  </joint>
  <link
    name="left front UL">
    <inertial>
      <origin
        xyz="-0.000209681593038635 0.0403703958248971 0.104221698379794"
        rpy="0 0 0" />
      <mass
        value="0.423016201461258" />
      <inertia
        ixx="0.00352758103464101"
        ixy="-1.18903041602086E-06"
        ixz="-9.5584362168216E-06"
        iyy="0.00368183782252195"
        iyz="-0.000143068160977384"
        izz="0.000251700053630159" />
    </inertial>
    <visual>
      <origin
        xyz="0 0 0"
        rpy="0 0 0" />
      <geometry>
        <mesh
          filename="package://quadf/meshes/left front UL.stl" />
      </geometry>
      <material
        name="">
        <color
          rgba="0.792156862745098 0.819607843137255 0.933333333333333 1" />
      </material>
    </visual>
    <collision>
      <origin
        xyz="0 0 0"
        rpy="0 0 0" />
      <geometry>
        <mesh
          filename="package://quadf/meshes/left front UL.stl" />
      </geometry>
    </collision>
  </link>
  <joint
    name="left front UL joint"
    type="revolute">
    <origin
      xyz="0.00170000000000001 0 0"
      rpy="-3.14159265358979 0 1.5707963267949" />
    <parent
      link="front left hip" />
    <child
      link="left front UL" />
    <axis
      xyz="0 1 0" />
    <limit
      lower="-6"
      upper="6"
      effort="9"
      velocity="5" />
  </joint>
  <link
    name="left front LL">
    <inertial>
      <origin
        xyz="-4.82947015711943E-15 0.00719227035186162 0.0979123541407718"
        rpy="0 0 0" />
      <mass
        value="0.18588320313603" />
      <inertia
        ixx="0.000942841477442434"
        ixy="1.54855627175905E-18"
        ixz="3.76723995243639E-15"
        iyy="0.000950744788421877"
        iyz="-4.9552792150223E-06"
        izz="2.53975387752843E-05" />
    </inertial>
    <visual>
      <origin
        xyz="0 0 0"
        rpy="0 0 0" />
      <geometry>
        <mesh
          filename="package://quadf/meshes/left front LL.stl" />
      </geometry>
      <material
        name="">
        <color
          rgba="0.101960784313725 0.101960784313725 0.101960784313725 1" />
      </material>
    </visual>
    <collision>
      <origin
        xyz="0 0 0"
        rpy="0 0 0" />
      <geometry>
        <mesh
          filename="package://quadf/meshes/left front LL.stl" />
      </geometry>
    </collision>
  </link>
  <joint
    name="left front LL joint"
    type="revolute">
    <origin
      xyz="0 0.0678 0.250000000000003"
      rpy="0 0 0" />
    <parent
      link="left front UL" />
    <child
      link="left front LL" />
    <axis
      xyz="0 1 0" />
    <limit
      lower="-6"
      upper="6"
      effort="9"
      velocity="5" />
  </joint>
  <link
    name="front right hip ">
    <inertial>
      <origin
        xyz="-0.000742117901801134 0.0882779459995091 0.000214154719464069"
        rpy="0 0 0" />
      <mass
        value="0.594830758051326" />
      <inertia
        ixx="0.00579009696104055"
        ixy="0.000114220085854743"
        ixz="3.18218078782749E-06"
        iyy="0.000693987589064899"
        iyz="-1.63944084824221E-05"
        izz="0.00554610693255237" />
    </inertial>
    <visual>
      <origin
        xyz="0 0 0"
        rpy="0 0 0" />
      <geometry>
        <mesh
          filename="package://quadf/meshes/front right hip .stl" />
      </geometry>
      <material
        name="">
        <color
          rgba="0.792156862745098 0.819607843137255 0.933333333333333 1" />
      </material>
    </visual>
    <collision>
      <origin
        xyz="0 0 0"
        rpy="0 0 0" />
      <geometry>
        <mesh
          filename="package://quadf/meshes/front right hip .stl" />
      </geometry>
    </collision>
  </link>
  <joint
    name="front right hip joint"
    type="revolute">
    <origin
      xyz="0.124999999999999 0.283000000000001 -0.0266306081677545"
      rpy="-3.14159265358979 0 0" />
    <parent
      link="base" />
    <child
      link="front right hip " />
    <axis
      xyz="0 -1 0" />
    <limit
      lower="-3.14"
      upper="3.14"
      effort="9"
      velocity="5" />
  </joint>
  <link
    name="right front UL">
    <inertial>
      <origin
        xyz="-0.000209681593037359 0.0403703958248838 0.1042216983798"
        rpy="0 0 0" />
      <mass
        value="0.423016201461258" />
      <inertia
        ixx="0.003527581034641"
        ixy="-1.18903041601998E-06"
        ixz="-9.55843621683405E-06"
        iyy="0.00368183782252204"
        iyz="-0.000143068160977384"
        izz="0.000251700053630252" />
    </inertial>
    <visual>
      <origin
        xyz="0 0 0"
        rpy="0 0 0" />
      <geometry>
        <mesh
          filename="package://quadf/meshes/right front UL.stl" />
      </geometry>
      <material
        name="">
        <color
          rgba="0.792156862745098 0.819607843137255 0.933333333333333 1" />
      </material>
    </visual>
    <collision>
      <origin
        xyz="0 0 0"
        rpy="0 0 0" />
      <geometry>
        <mesh
          filename="package://quadf/meshes/right front UL.stl" />
      </geometry>
    </collision>
  </link>
  <joint
    name="right front UL joint"
    type="revolute">
    <origin
      xyz="0.00169999999999995 0 0"
      rpy="0 0 -1.5707963267949" />
    <parent
      link="front right hip " />
    <child
      link="right front UL" />
    <axis
      xyz="0 1 0" />
    <limit
      lower="-6"
      upper="6"
      effort="9"
      velocity="5" />
  </joint>
  <link
    name="right front LL">
    <inertial>
      <origin
        xyz="-7.27196081129478E-15 0.00719227035185829 0.0979123541407722"
        rpy="0 0 0" />
      <mass
        value="0.185883203136022" />
      <inertia
        ixx="0.000942841477442774"
        ixy="3.64831777228061E-18"
        ixz="3.36833300639854E-15"
        iyy="0.000950744788424826"
        iyz="-4.95527921502276E-06"
        izz="2.53975387778962E-05" />
    </inertial>
    <visual>
      <origin
        xyz="0 0 0"
        rpy="0 0 0" />
      <geometry>
        <mesh
          filename="package://quadf/meshes/right front LL.stl" />
      </geometry>
      <material
        name="">
        <color
          rgba="0.101960784313725 0.101960784313725 0.101960784313725 1" />
      </material>
    </visual>
    <collision>
      <origin
        xyz="0 0 0"
        rpy="0 0 0" />
      <geometry>
        <mesh
          filename="package://quadf/meshes/right front LL.stl" />
      </geometry>
    </collision>
  </link>
  <joint
    name="right front LL joint"
    type="revolute">
    <origin
      xyz="0 0.0677999999999798 0.250000000000016"
      rpy="0 0 0" />
    <parent
      link="right front UL" />
    <child
      link="right front LL" />
    <axis
      xyz="0 1 0" />
    <limit
      lower="-6"
      upper="6"
      effort="9"
      velocity="5" />
  </joint>
  <link
    name="Back left hip">
    <inertial>
      <origin
        xyz="-0.000742117901777875 0.0882779459995155 0.000214154719464728"
        rpy="0 0 0" />
      <mass
        value="0.594830758051326" />
      <inertia
        ixx="0.00579009696104056"
        ixy="0.000114220085854743"
        ixz="3.18218078782762E-06"
        iyy="0.0006939875890649"
        iyz="-1.63944084824232E-05"
        izz="0.00554610693255238" />
    </inertial>
    <visual>
      <origin
        xyz="0 0 0"
        rpy="0 0 0" />
      <geometry>
        <mesh
          filename="package://quadf/meshes/Back left hip.stl" />
      </geometry>
      <material
        name="">
        <color
          rgba="0.792156862745098 0.819607843137255 0.933333333333333 1" />
      </material>
    </visual>
    <collision>
      <origin
        xyz="0 0 0"
        rpy="0 0 0" />
      <geometry>
        <mesh
          filename="package://quadf/meshes/Back left hip.stl" />
      </geometry>
    </collision>
  </link>
  <joint
    name="Back left hip joint"
    type="revolute">
    <origin
      xyz="-0.125000000000011 -0.310800000000001 -0.0266306081677699"
      rpy="3.14159265358979 0 -3.14159265358979" />
    <parent
      link="base" />
    <child
      link="Back left hip" />
    <axis
      xyz="0 -1 0" />
    <limit
      lower="-3.14"
      upper="3.14"
      effort="9"
      velocity="5" />
  </joint>
  <link
    name="left back UL">
    <inertial>
      <origin
        xyz="-0.000209681593043909 0.0403703958249091 0.104221698379799"
        rpy="0 0 0" />
      <mass
        value="0.423016201461257" />
      <inertia
        ixx="0.003527581034641"
        ixy="-1.18903041602077E-06"
        ixz="-9.55843621681877E-06"
        iyy="0.00368183782252201"
        iyz="-0.000143068160977384"
        izz="0.000251700053630218" />
    </inertial>
    <visual>
      <origin
        xyz="0 0 0"
        rpy="0 0 0" />
      <geometry>
        <mesh
          filename="package://quadf/meshes/left back UL.stl" />
      </geometry>
      <material
        name="">
        <color
          rgba="0.792156862745098 0.819607843137255 0.933333333333333 1" />
      </material>
    </visual>
    <collision>
      <origin
        xyz="0 0 0"
        rpy="0 0 0" />
      <geometry>
        <mesh
          filename="package://quadf/meshes/left back UL.stl" />
      </geometry>
    </collision>
  </link>
  <joint
    name="left back UL joint"
    type="revolute">
    <origin
      xyz="0.00169999999999795 0 0"
      rpy="0 0 -1.5707963267949" />
    <parent
      link="Back left hip" />
    <child
      link="left back UL" />
    <axis
      xyz="0 1 0" />
    <limit
      lower="-6"
      upper="6"
      effort="9"
      velocity="5" />
  </joint>
  <link
    name="left back LL">
    <inertial>
      <origin
        xyz="-4.38538094726937E-15 0.00719227035185818 0.0979123541407708"
        rpy="0 0 0" />
      <mass
        value="0.185883203136021" />
      <inertia
        ixx="0.000942841477442421"
        ixy="-7.81846998391496E-18"
        ixz="3.12086796242812E-15"
        iyy="0.000950744788424168"
        iyz="-4.95527921502166E-06"
        izz="2.53975387775872E-05" />
    </inertial>
    <visual>
      <origin
        xyz="0 0 0"
        rpy="0 0 0" />
      <geometry>
        <mesh
          filename="package://quadf/meshes/left back LL.stl" />
      </geometry>
      <material
        name="">
        <color
          rgba="0.101960784313725 0.101960784313725 0.101960784313725 1" />
      </material>
    </visual>
    <collision>
      <origin
        xyz="0 0 0"
        rpy="0 0 0" />
      <geometry>
        <mesh
          filename="package://quadf/meshes/left back LL.stl" />
      </geometry>
    </collision>
  </link>
  <joint
    name="left back LL joint"
    type="revolute">
    <origin
      xyz="0 0.067800000000012 0.250000000000008"
      rpy="0 0 0" />
    <parent
      link="left back UL" />
    <child
      link="left back LL" />
    <axis
      xyz="0 1 0" />
    <limit
      lower="-6"
      upper="6"
      effort="9"
      velocity="5" />
  </joint>
  <link
    name="Back right hip">
    <inertial>
      <origin
        xyz="-0.000727243703443806 0.092112342193215 -0.000198984132470569"
        rpy="0 0 0" />
      <mass
        value="0.601866556488004" />
      <inertia
        ixx="0.00596933210385933"
        ixy="0.000111385467813034"
        ixz="-2.69131549086511E-06"
        iyy="0.000696524079127736"
        iyz="1.5567012022586E-05"
        izz="0.00572460287072934" />
    </inertial>
    <visual>
      <origin
        xyz="0 0 0"
        rpy="0 0 0" />
      <geometry>
        <mesh
          filename="package://quadf/meshes/Back right hip.stl" />
      </geometry>
      <material
        name="">
        <color
          rgba="0.792156862745098 0.819607843137255 0.933333333333333 1" />
      </material>
    </visual>
    <collision>
      <origin
        xyz="0 0 0"
        rpy="0 0 0" />
      <geometry>
        <mesh
          filename="package://quadf/meshes/Back right hip.stl" />
      </geometry>
    </collision>
  </link>
  <joint
    name="Back right hip joint"
    type="revolute">
    <origin
      xyz="0.12499999999998 -0.3103 -0.0266306081677744"
      rpy="0 0 0" />
    <parent
      link="base" />
    <child
      link="Back right hip" />
    <axis
      xyz="0 1 0" />
    <limit
      lower="-3.14"
      upper="3.14"
      effort="9"
      velocity="5" />
  </joint>
  <link
    name="right back UL">
    <inertial>
      <origin
        xyz="-0.000209681593039857 0.0403703958248969 0.104221698379792"
        rpy="0 0 0" />
      <mass
        value="0.423016201461257" />
      <inertia
        ixx="0.003527581034641"
        ixy="-1.18903041601913E-06"
        ixz="-9.55843621683442E-06"
        iyy="0.00368183782252197"
        iyz="-0.000143068160977384"
        izz="0.000251700053630182" />
    </inertial>
    <visual>
      <origin
        xyz="0 0 0"
        rpy="0 0 0" />
      <geometry>
        <mesh
          filename="package://quadf/meshes/right back UL.stl" />
      </geometry>
      <material
        name="">
        <color
          rgba="0.792156862745098 0.819607843137255 0.933333333333333 1" />
      </material>
    </visual>
    <collision>
      <origin
        xyz="0 0 0"
        rpy="0 0 0" />
      <geometry>
        <mesh
          filename="package://quadf/meshes/right back UL.stl" />
      </geometry>
    </collision>
  </link>
  <joint
    name="right back UL joint"
    type="revolute">
    <origin
      xyz="0.00169999999999998 0 0"
      rpy="-3.14159265358979 0 1.5707963267949" />
    <parent
      link="Back right hip" />
    <child
      link="right back UL" />
    <axis
      xyz="0 1 0" />
    <limit
      lower="-6"
      upper="6"
      effort="9"
      velocity="5" />
  </joint>
  <link
    name="right back LL">
    <inertial>
      <origin
        xyz="-6.93889390390723E-15 0.00719227035185524 0.0979123541407748"
        rpy="0 0 0" />
      <mass
        value="0.185883203136021" />
      <inertia
        ixx="0.00094284147744289"
        ixy="6.66708551010558E-18"
        ixz="3.83979606638839E-15"
        iyy="0.000950744788423458"
        iyz="-4.95527921502387E-06"
        izz="2.53975387764063E-05" />
    </inertial>
    <visual>
      <origin
        xyz="0 0 0"
        rpy="0 0 0" />
      <geometry>
        <mesh
          filename="package://quadf/meshes/right back LL.stl" />
      </geometry>
      <material
        name="">
        <color
          rgba="0.101960784313725 0.101960784313725 0.101960784313725 1" />
      </material>
    </visual>
    <collision>
      <origin
        xyz="0 0 0"
        rpy="0 0 0" />
      <geometry>
        <mesh
          filename="package://quadf/meshes/right back LL.stl" />
      </geometry>
    </collision>
  </link>
  <joint
    name="right back LL joint"
    type="revolute">
    <origin
      xyz="0 0.0678000000000027 0.25"
      rpy="0 -0.00644318629091657 0" />
    <parent
      link="right back UL" />
    <child
      link="right back LL" />
    <axis
      xyz="0 1 0" />
    <limit
      lower="-6"
      upper="6"
      effort="9"
      velocity="5" />
  </joint>
</robot>